Блок `catch` получает аргумент `x`. Это не тот же `x`, который определен в качестве переменной перед строкой `try {`

Затем мы присваиваем этому аргументу значение `1` и устанавливаем значение для переменной `y`. Потом выводим в консоль значение аргумента `x`, которое равно `1`.

За пределами блока `catch` переменная `x` все еще `undefined`, а `y` равно `2`. Когда мы вызываем `console.log(x)` за пределами блока `catch`, этот вызов возвращает `undefined`, а `y` возвращает `2`.
